Workbook

Sheet Summary
A1: Golden dataset: expected reconciliation results (answer key)
A2: Business date 2026-09-22 · tolerance $0.50 · fuzzy window ±24h · timing cut-off 22:00 · payments extract window 2026-09-22 00:00 to next day 06:00 (EAT)
A4: Expected status | B4: Roll-up | C4: Count
A5: MATCHED | B5: Match | C5: =COUNTIF('Expected results'!H:H,A5) -> 33
A6: MATCHED_TOLERANCE | B6: Match | C6: =COUNTIF('Expected results'!H:H,A6) -> 3
A7: MATCHED_SPLIT | B7: Match | C7: =COUNTIF('Expected results'!H:H,A7) -> 3
A8: MATCHED_FUZZY | B8: Match (flagged) | C8: =COUNTIF('Expected results'!H:H,A8) -> 4
A9: VARIANCE | B9: Variance | C9: =COUNTIF('Expected results'!H:H,A9) -> 4
A10: POSTING_MISMATCH | B10: Variance | C10: =COUNTIF('Expected results'!H:H,A10) -> 2
A11: MISSING_PAYMENT | B11: Exception | C11: =COUNTIF('Expected results'!H:H,A11) -> 5
A12: PENDING_TIMING | B12: Exception (soft) | C12: =COUNTIF('Expected results'!H:H,A12) -> 2
A13: UNMATCHED_PAYMENT | B13: Exception | C13: =COUNTIF('Expected results'!H:H,A13) -> 4
A14: MISSING_POSTING | B14: Exception | C14: =COUNTIF('Expected results'!H:H,A14) -> 3
A15: DUPLICATE_PAYMENT | B15: Exception | C15: =COUNTIF('Expected results'!H:H,A15) -> 2
A16: Total reconciled items | C16: =SUM(C5:C15) -> 65
A17: Quarantined rows (data quality) | C17: =COUNTA(Quarantine!A:A)-1 -> 6
A19: Input row counts
A20: sales rows | C20: 62
A21: payment rows | C21: 63
A22: posting rows | C22: 57

Sheet Expected results
A1: transaction_id | B1: payment_ids | C1: journal_id | D1: expected_amount | E1: actual_amount | F1: posted_amount | G1: variance | H1: expected_status | I1: roll_up | J1: rule_id | K1: scenario | L1: note
A2: TUP-S-000001 | B2: SCNO6B9M80 | C2: JNL-2026-000001 | D2: 31 | E2: 31 | F2: 31 | G2: =IF(AND(ISNUMBER(E2),ISNUMBER(D2)),E2-D2,"") -> 0 | H2: MATCHED | I2: Match | J2: R1+R4+R6 | K2: Clean match
A3: TUP-S-000002 | B3: BNK511615594 | C3: JNL-2026-000002 | D3: 435 | E3: 435 | F3: 435 | G3: =IF(AND(ISNUMBER(E3),ISNUMBER(D3)),E3-D3,"") -> 0 | H3: MATCHED | I3: Match | J3: R1+R4+R6 | K3: Clean match
A4: TUP-S-000003 | B4: SCCOSFOGYR | C4: JNL-2026-000003 | D4: 577.5 | E4: 577.5 | F4: 577.5 | G4: =IF(AND(ISNUMBER(E4),ISNUMBER(D4)),E4-D4,"") -> 0 | H4: MATCHED | I4: Match | J4: R1+R4+R6 | K4: Clean match
A5: TUP-S-000004 | B5: SQYR9OUDOC | C5: JNL-2026-000004 | D5: 33.6 | E5: 33.6 | F5: 33.6 | G5: =IF(AND(ISNUMBER(E5),ISNUMBER(D5)),E5-D5,"") -> 0 | H5: MATCHED | I5: Match | J5: R1+R4+R6 | K5: Clean match
A6: TUP-S-000005 | B6: SJIP98Q1ZX | C6: JNL-2026-000005 | D6: 72.8 | E6: 72.8 | F6: 72.8 | G6: =IF(AND(ISNUMBER(E6),ISNUMBER(D6)),E6-D6,"") -> 0 | H6: MATCHED | I6: Match | J6: R1+R4+R6 | K6: Clean match
A7: TUP-S-000006 | B7: SV37Q9AH8R | C7: JNL-2026-000006 | D7: 612 | E7: 612 | F7: 612 | G7: =IF(AND(ISNUMBER(E7),ISNUMBER(D7)),E7-D7,"") -> 0 | H7: MATCHED | I7: Match | J7: R1+R4+R6 | K7: Clean match
A8: TUP-S-000007 | B8: BNK489325288 | C8: JNL-2026-000007 | D8: 22.4 | E8: 22.4 | F8: 22.4 | G8: =IF(AND(ISNUMBER(E8),ISNUMBER(D8)),E8-D8,"") -> 0 | H8: MATCHED | I8: Match | J8: R1+R4+R6 | K8: Clean match
A9: TUP-S-000008 | B9: BNK171822782 | C9: JNL-2026-000008 | D9: 30.8 | E9: 30.8 | F9: 30.8 | G9: =IF(AND(ISNUMBER(E9),ISNUMBER(D9)),E9-D9,"") -> 0 | H9: MATCHED | I9: Match | J9: R1+R4+R6 | K9: Clean match
A10: TUP-S-000009 | B10: SHOEVB9OOA | C10: JNL-2026-000009 | D10: 7 | E10: 7 | F10: 7 | G10: =IF(AND(ISNUMBER(E10),ISNUMBER(D10)),E10-D10,"") -> 0 | H10: MATCHED | I10: Match | J10: R1+R4+R6 | K10: Clean match
A11: TUP-S-000010 | B11: STI4P40MGG | C11: JNL-2026-000010 | D11: 308 | E11: 308 | F11: 308 | G11: =IF(AND(ISNUMBER(E11),ISNUMBER(D11)),E11-D11,"") -> 0 | H11: MATCHED | I11: Match | J11: R1+R4+R6 | K11: Clean match
A12: TUP-S-000011 | B12: SG82I1LR3P | C12: JNL-2026-000011 | D12: 288 | E12: 288 | F12: 288 | G12: =IF(AND(ISNUMBER(E12),ISNUMBER(D12)),E12-D12,"") -> 0 | H12: MATCHED | I12: Match | J12: R1+R4+R6 | K12: Clean match
A13: TUP-S-000012 | B13: SNDKYAYQ3S | C13: JNL-2026-000012 | D13: 435 | E13: 435 | F13: 435 | G13: =IF(AND(ISNUMBER(E13),ISNUMBER(D13)),E13-D13,"") -> 0 | H13: MATCHED | I13: Match | J13: R1+R4+R6 | K13: Clean match
... A31: TUP-S-000030 | B31: SXHN3QXKHK | C31: JNL-2026-000030 | D31: 12.6 | E31: 12.6 | F31: 12.6 | G31: =IF(AND(ISNUMBER(E31),ISNUMBER(D31)),E31-D31,"") -> 0 | H31: MATCHED | I31: Match | J31: R1+R4+R6 | K31: Clean match
A32: TUP-S-000031 | B32: SKHCW81XE6 | C32: JNL-2026-000031 | D32: 589 | E32: 589.25 | F32: 589 | G32: =IF(AND(ISNUMBER(E32),ISNUMBER(D32)),E32-D32,"") -> 0.25 | H32: MATCHED_TOLERANCE | I32: Match | J32: R1+R4 | K32: Rounding difference within $0.50 | L32: diff 0.25
A33: TUP-S-000032 | B33: SWR8431RUP | C33: JNL-2026-000032 | D33: 5.6 | E33: 5.85 | F33: 5.6 | G33: =IF(AND(ISNUMBER(E33),ISNUMBER(D33)),E33-D33,"") -> 0.25 | H33: MATCHED_TOLERANCE | I33: Match | J33: R1+R4 | K33: Rounding difference within $0.50 | L33: diff 0.25
A34: TUP-S-000033 | B34: SGWQVRR9A7 | C34: JNL-2026-000033 | D34: 279 | E34: 279.4 | F34: 279 | G34: =IF(AND(ISNUMBER(E34),ISNUMBER(D34)),E34-D34,"") -> 0.4 | H34: MATCHED_TOLERANCE | I34: Match | J34: R1+R4 | K34: Rounding difference within $0.50 | L34: diff 0.40
A35: TUP-S-000034 | B35: SXX497W19V, SQRTQOHMUH | C35: JNL-2026-000034 | D35: 77 | E35: 77 | F35: 77 | G35: =IF(AND(ISNUMBER(E35),ISNUMBER(D35)),E35-D35,"") -> 0 | H35: MATCHED_SPLIT | I35: Match | J35: R2 | K35: Paid in 2 instalments
A36: TUP-S-000035 | B36: SKA8IRCD9S, SE5GAS442V | C36: JNL-2026-000035 | D36: 62 | E36: 62 | F36: 62 | G36: =IF(AND(ISNUMBER(E36),ISNUMBER(D36)),E36-D36,"") -> 0 | H36: MATCHED_SPLIT | I36: Match | J36: R2 | K36: Paid in 2 instalments
A37: TUP-S-000036 | B37: BNK131869993, SN22T1TDGN | C37: JNL-2026-000036 | D37: 115.5 | E37: 115.5 | F37: 115.5 | G37: =IF(AND(ISNUMBER(E37),ISNUMBER(D37)),E37-D37,"") -> 0 | H37: MATCHED_SPLIT | I37: Match | J37: R2 | K37: Paid in 2 instalments
A38: TUP-S-000037 | B38: SY4SCOSS3E | C38: JNL-2026-000037 | D38: 37.8 | E38: 37.8 | F38: 37.8 | G38: =IF(AND(ISNUMBER(E38),ISNUMBER(D38)),E38-D38,"") -> 0 | H38: MATCHED_FUZZY | I38: Match (flagged) | J38: R3 | K38: Reference blank; matched on phone + amount + time | L38: payment reference = ''
A39: TUP-S-000038 | B39: BNK210249947 | C39: JNL-2026-000038 | D39: 37.8 | E39: 37.8 | F39: 37.8 | G39: =IF(AND(ISNUMBER(E39),ISNUMBER(D39)),E39-D39,"") -> 0 | H39: MATCHED_FUZZY | I39: Match (flagged) | J39: R3 | K39: Reference blank; matched on phone + amount + time | L39: payment reference = ''
A40: TUP-S-000039 | B40: SPUQBFOBRC | C40: JNL-2026-000039 | D40: 435 | E40: 435 | F40: 435 | G40: =IF(AND(ISNUMBER(E40),ISNUMBER(D40)),E40-D40,"") -> 0 | H40: MATCHED_FUZZY | I40: Match (flagged) | J40: R3 | K40: Reference truncated; matched on phone + amount + time | L40: payment reference = 'TUP-S-00003'
A41: TUP-S-000040 | B41: SLUGKV05SZ | C41: JNL-2026-000040 | D41: 576 | E41: 576 | F41: 576 | G41: =IF(AND(ISNUMBER(E41),ISNUMBER(D41)),E41-D41,"") -> 0 | H41: MATCHED_FUZZY | I41: Match (flagged) | J41: R3 | K41: Reference garbled; matched on phone + amount + time | L41: payment reference = 'TUPS000040'
A42: TUP-S-000041 | B42: SBM7X52DNR | C42: JNL-2026-000041 | D42: 77 | E42: 27 | F42: 77 | G42: =IF(AND(ISNUMBER(E42),ISNUMBER(D42)),E42-D42,"") -> -50 | H42: VARIANCE | I42: Variance | J42: R4 | K42: Under-payment
A43: TUP-S-000042 | B43: SHH3HJ5S6R | C43: JNL-2026-000042 | D43: 145 | E43: 95 | F43: 145 | G43: =IF(AND(ISNUMBER(E43),ISNUMBER(D43)),E43-D43,"") -> -50 | H43: VARIANCE | I43: Variance | J43: R4 | K43: Under-payment
A44: TUP-S-000043 | B44: SPV6RAST5J | C44: JNL-2026-000043 | D44: 308 | E44: 288 | F44: 308 | G44: =IF(AND(ISNUMBER(E44),ISNUMBER(D44)),E44-D44,"") -> -20 | H44: VARIANCE | I44: Variance | J44: R4 | K44: Under-payment
A45: TUP-S-000044 | B45: SPCU4YYJ5C | C45: JNL-2026-000044 | D45: 77 | E45: 115.5 | F45: 77 | G45: =IF(AND(ISNUMBER(E45),ISNUMBER(D45)),E45-D45,"") -> 38.5 | H45: VARIANCE | I45: Variance | J45: R4 | K45: Over-payment
A46: TUP-S-000045 | B46: SWJE4QVZFV | C46: JNL-2026-000045 | D46: 6.65 | E46: 6.65 | F46: 31.65 | G46: =IF(AND(ISNUMBER(E46),ISNUMBER(D46)),E46-D46,"") -> 0 | H46: POSTING_MISMATCH | I46: Variance | J46: R6 | K46: ERP posted a different amount
A47: TUP-S-000046 | B47: BNK172400504 | C47: JNL-2026-000046 | D47: 89.6 | E47: 89.6 | F47: 86.4 | G47: =IF(AND(ISNUMBER(E47),ISNUMBER(D47)),E47-D47,"") -> 0 | H47: POSTING_MISMATCH | I47: Variance | J47: R6 | K47: ERP posted a different amount
A48: TUP-S-000047 | C48: JNL-2026-000047 | D48: 288 | F48: 288 | H48: MISSING_PAYMENT | I48: Exception | J48: R7 | K48: Sale never paid
A49: TUP-S-000048 | C49: JNL-2026-000048 | D49: 480 | F49: 480 | H49: MISSING_PAYMENT | I49: Exception | J49: R7 | K49: Sale never paid
A50: TUP-S-000049 | C50: JNL-2026-000049 | D50: 290 | F50: 290 | H50: MISSING_PAYMENT | I50: Exception | J50: R7 | K50: Sale never paid
A51: TUP-S-000050 | C51: JNL-2026-000050 | D51: 28 | F51: 28 | H51: PENDING_TIMING | I51: Exception (soft) | J51: R7 | K51: Late sale (after 22:00 cut-off), payment not yet received | L51: carry forward to next run
A52: TUP-S-000051 | C52: JNL-2026-000051 | D52: 54.6 | F52: 54.6 | H52: PENDING_TIMING | I52: Exception (soft) | J52: R7 | K52: Late sale (after 22:00 cut-off), payment not yet received | L52: carry forward to next run
B53: BNK974395339 | E53: 15 | H53: UNMATCHED_PAYMENT | I53: Exception | J53: R7 | K53: Payment with no corresponding sale
B54: SL0LMI8X76 | E54: 800 | H54: UNMATCHED_PAYMENT | I54: Exception | J54: R7 | K54: Payment with no corresponding sale
B55: SXZ9XFZAQ8 | E55: 64.4 | H55: UNMATCHED_PAYMENT | I55: Exception | J55: R7 | K55: Payment with no corresponding sale
A56: TUP-S-000052 | B56: SYT0HICCT5 | D56: 248 | E56: 248 | G56: =IF(AND(ISNUMBER(E56),ISNUMBER(D56)),E56-D56,"") -> 0 | H56: MISSING_POSTING | I56: Exception | J56: R6 | K56: Paid but not posted to ERP
A57: TUP-S-000053 | B57: SPG50RCXN2 | D57: 248 | E57: 248 | G57: =IF(AND(ISNUMBER(E57),ISNUMBER(D57)),E57-D57,"") -> 0 | H57: MISSING_POSTING | I57: Exception | J57: R6 | K57: Paid but not posted to ERP
...

Sheet Quarantine
A1: source | B1: record_key | C1: reason
A2: sales | B2: (blank) | C2: Missing required field: transaction_id
A3: sales | B3: TUP-S-000959 | C3: Amount must be greater than 0
A4: sales | B4: TUP-S-000960 | C4: Invalid phone format (expected 2547XXXXXXXX)
A5: payments | B5: SXH0W1DSTW | C5: Unparseable timestamp
A6: payments | B6: SHGW9XHRO1 | C6: Invalid channel 'CASH'
A7: postings | B7: TUP-S-000961 | C7: Unsupported currency 'KES' (USD only)

Sheet Rules reference
A1: Rule | B1: Name | C1: Definition
A2: R1 | B2: Exact key | C2: Sale transaction_id = payment reference (exactly one payment).
A3: R2 | B3: Split | C3: Several payments reference one sale and together equal the expected amount (± tolerance).
A4: R3 | B4: Fuzzy | C4: Unreferenced payment matched on same phone + amount (± tolerance) + within ±24h. One-to-one only; ties are not matched.
A5: R4 | B5: Amount check | C5: |actual − expected| ≤ $0.50 → match; otherwise VARIANCE.
A6: R5 | B6: Duplicates | C6: Checked before matching: same receipt twice, or same reference + amount within 5 minutes. Extra copy → DUPLICATE_PAYMENT.
A7: R6 | B7: Posting check | C7: Matched pair: no POSTED ERP line → MISSING_POSTING; posted ≠ expected → POSTING_MISMATCH.
A8: R7 | B8: Leftovers | C8: Unpaid sale → MISSING_PAYMENT (PENDING_TIMING if after 22:00 cut-off); payment with no sale → UNMATCHED_PAYMENT.
A9: Precedence | C9: Variance is reported before posting checks: a VARIANCE item with a correct posting stays VARIANCE.
